Workbook
Name Slicer_Department: #N/A
Name Slicer_Month: #N/A
Name tblRawData: #REF!

Sheet Employees
A1: EmployeeID | B1: Name | C1: Gender | D1: DOB | E1: DOJ | F1: Department | G1: JobRole | H1: Manager | I1: EmploymentType | J1: Grade
A2: EMP001 | B2: Liam Smith | C2: Male | D2: 32888 | E2: 43862 | F2: IT | G2: Software Engineer | H2: Manish Sharma | I2: Full-Time | J2: Grade 3
A3: EMP002 | B3: Emma Smith | C3: Female | D3: 33685 | E3: 44270 | F3: HR | G3: HR Executive | H3: Anita Desai | I3: Full-Time | J3: Grade 2
A4: EMP003 | B4: Noah Smith | C4: Male | D4: 32273 | E4: 43687 | F4: Finance | G4: Accountant | H4: Suresh Kumar | I4: Full-Time | J4: Grade 3
A5: EMP004 | B5: Olivia Smith | C5: Female | D5: 34885 | E5: 44713 | F5: Operations | G5: Operations Associate | H5: Meera Nair | I5: Contract | J5: Grade 1
A6: EMP005 | B6: Oliver Smith | C6: Male | D6: 33462 | E6: 44459 | F6: IT | G6: Team Lead | H6: Manish Sharma | I6: Full-Time | J6: Grade 4
A7: EMP006 | B7: Ava Smith | C7: Female | D7: 34292 | E7: 44907 | F7: HR | G7: HR Manager | H7: Anita Desai | I7: Full-Time | J7: Grade 4
A8: EMP007 | B8: Elijah Smith | C8: Male | D8: 32867 | E8: 43105 | F8: Finance | G8: Financial Analyst | H8: Suresh Kumar | I8: Full-Time | J8: Grade 3
A9: EMP008 | B9: Sophia Smith | C9: Female | D9: 35368 | E9: 45122 | F9: Operations | G9: Operations Manager | H9: Meera Nair | I9: Full-Time | J9: Grade 4
A10: EMP009 | B10: William Smith | C10: Male | D10: 34373 | E10: 44844 | F10: IT | G10: Software Engineer | H10: Manish Sharma | I10: Part-Time | J10: Grade 2
A11: EMP010 | B11: Isabella Smith | C11: Female | D11: 35534 | E11: 45231 | F11: Finance | G11: Accountant | H11: Suresh Kumar | I11: Intern | J11: Grade 1
A12: EMP011 | B12: Liam Johnson | C12: Male | D12: 32889 | E12: 43863 | F12: IT | G12: Software Engineer | H12: Manish Sharma | I12: Full-Time | J12: Grade 3
A13: EMP012 | B13: Emma Johnson | C13: Female | D13: 33686 | E13: 44271 | F13: HR | G13: HR Executive | H13: Anita Desai | I13: Full-Time | J13: Grade 2
... A101: EMP100 | B101: Isabella Martinez | C101: Female | D101: 35543 | E101: 45240 | F101: Finance | G101: Accountant | H101: Suresh Kumar | I101: Intern | J101: Grade 1

Sheet Attendance
A1: EmployeeID | B1: Date | C1: Status | D1: InTime | E1: OutTime | F1: OvertimeHrs | G1: Attendance %
A2: EMP001 | B2: 46174 | C2: P | D2: 0.375 | E2: 0.75 | F2: 0 | G2: =IF(OR(tblAttendance.[[#This Row],[Status]]="P",tblAttendance.[[#This Row],[Status]]="WFH"),100%,IF(tblAttendance.[[#This Row],[Status]]="L",0%,IF(tblAttendance.[[#This Row],[Status]]="A",0%,0%))) -> 1
A3: EMP002 | B3: 46174 | C3: P | D3: 0.375 | E3: 0.77083333 | F3: 0.5 | G3: =IF(OR(tblAttendance.[[#This Row],[Status]]="P",tblAttendance.[[#This Row],[Status]]="WFH"),100%,IF(tblAttendance.[[#This Row],[Status]]="L",0%,IF(tblAttendance.[[#This Row],[Status]]="A",0%,0%))) -> 1
A4: EMP003 | B4: 46174 | C4: A | D4: 0 | E4: 0 | F4: 0 | G4: =IF(OR(tblAttendance.[[#This Row],[Status]]="P",tblAttendance.[[#This Row],[Status]]="WFH"),100%,IF(tblAttendance.[[#This Row],[Status]]="L",0%,IF(tblAttendance.[[#This Row],[Status]]="A",0%,0%))) -> 0
A5: EMP004 | B5: 46174 | C5: P | D5: 0.38541667 | E5: 0.75 | F5: 0 | G5: =IF(OR(tblAttendance.[[#This Row],[Status]]="P",tblAttendance.[[#This Row],[Status]]="WFH"),100%,IF(tblAttendance.[[#This Row],[Status]]="L",0%,IF(tblAttendance.[[#This Row],[Status]]="A",0%,0%))) -> 1
A6: EMP005 | B6: 46174 | C6: WFH | D6: 0.375 | E6: 0.75 | F6: 0 | G6: =IF(OR(tblAttendance.[[#This Row],[Status]]="P",tblAttendance.[[#This Row],[Status]]="WFH"),100%,IF(tblAttendance.[[#This Row],[Status]]="L",0%,IF(tblAttendance.[[#This Row],[Status]]="A",0%,0%))) -> 1
A7: EMP006 | B7: 46174 | C7: P | D7: 0.375 | E7: 0.75 | F7: 0 | G7: =IF(OR(tblAttendance.[[#This Row],[Status]]="P",tblAttendance.[[#This Row],[Status]]="WFH"),100%,IF(tblAttendance.[[#This Row],[Status]]="L",0%,IF(tblAttendance.[[#This Row],[Status]]="A",0%,0%))) -> 1
A8: EMP007 | B8: 46174 | C8: P | D8: 0.375 | E8: 0.79166667 | F8: 1 | G8: =IF(OR(tblAttendance.[[#This Row],[Status]]="P",tblAttendance.[[#This Row],[Status]]="WFH"),100%,IF(tblAttendance.[[#This Row],[Status]]="L",0%,IF(tblAttendance.[[#This Row],[Status]]="A",0%,0%))) -> 1
A9: EMP008 | B9: 46174 | C9: P | D9: 0.375 | E9: 0.75 | F9: 0 | G9: =IF(OR(tblAttendance.[[#This Row],[Status]]="P",tblAttendance.[[#This Row],[Status]]="WFH"),100%,IF(tblAttendance.[[#This Row],[Status]]="L",0%,IF(tblAttendance.[[#This Row],[Status]]="A",0%,0%))) -> 1
A10: EMP009 | B10: 46174 | C10: L | D10: 0 | E10: 0 | F10: 0 | G10: =IF(OR(tblAttendance.[[#This Row],[Status]]="P",tblAttendance.[[#This Row],[Status]]="WFH"),100%,IF(tblAttendance.[[#This Row],[Status]]="L",0%,IF(tblAttendance.[[#This Row],[Status]]="A",0%,0%))) -> 0
A11: EMP010 | B11: 46174 | C11: P | D11: 0.375 | E11: 0.75 | F11: 0 | G11: =IF(OR(tblAttendance.[[#This Row],[Status]]="P",tblAttendance.[[#This Row],[Status]]="WFH"),100%,IF(tblAttendance.[[#This Row],[Status]]="L",0%,IF(tblAttendance.[[#This Row],[Status]]="A",0%,0%))) -> 1
A12: EMP011 | B12: 46174 | C12: P | D12: 0.375 | E12: 0.75 | F12: 0 | G12: =IF(OR(tblAttendance.[[#This Row],[Status]]="P",tblAttendance.[[#This Row],[Status]]="WFH"),100%,IF(tblAttendance.[[#This Row],[Status]]="L",0%,IF(tblAttendance.[[#This Row],[Status]]="A",0%,0%))) -> 1
A13: EMP012 | B13: 46174 | C13: P | D13: 0.375 | E13: 0.75 | F13: 0 | G13: =IF(OR(tblAttendance.[[#This Row],[Status]]="P",tblAttendance.[[#This Row],[Status]]="WFH"),100%,IF(tblAttendance.[[#This Row],[Status]]="L",0%,IF(tblAttendance.[[#This Row],[Status]]="A",0%,0%))) -> 1
... A101: EMP100 | B101: 46177 | C101: P | D101: 0.375 | E101: 0.75 | F101: 0 | G101: =IF(OR(tblAttendance.[[#This Row],[Status]]="P",tblAttendance.[[#This Row],[Status]]="WFH"),100%,IF(tblAttendance.[[#This Row],[Status]]="L",0%,IF(tblAttendance.[[#This Row],[Status]]="A",0%,0%))) -> 1

Sheet Performance
A1: EmpID | B1: ReviewPeriod | C1: KRA1 | D1: KRA2 | E1: KRA3 | F1: KRA4 | G1: KRA5 | H1: ManagerScore | I1: PeerScore | J1: Awards | K1: KRA Avg | L1: PerfScore
A2: EMP001 | B2: 2026-Q1 | C2: 4 | D2: 5 | E2: 4 | F2: 3 | G2: 4 | H2: 4 | I2: 4 | J2: N | K2: =AVERAGE(tblPerformance[[#This Row],[KRA1]:[KRA5]]) -> 4 | L2: =ROUND((K2*0.6)+(H2*0.3)+(I2*0.1),2) -> 4
A3: EMP002 | B3: 2026-Q1 | C3: 5 | D3: 5 | E3: 5 | F3: 4 | G3: 5 | H3: 5 | I3: 5 | J3: Y | K3: =AVERAGE(tblPerformance[[#This Row],[KRA1]:[KRA5]]) -> 4.8 | L3: =ROUND((K3*0.6)+(H3*0.3)+(I3*0.1),2) -> 4.88
A4: EMP003 | B4: 2026-Q1 | C4: 3 | D4: 3 | E4: 4 | F4: 3 | G4: 3 | H4: 3 | I4: 3 | J4: N | K4: =AVERAGE(tblPerformance[[#This Row],[KRA1]:[KRA5]]) -> 3.2 | L4: =ROUND((K4*0.6)+(H4*0.3)+(I4*0.1),2) -> 3.12
A5: EMP004 | B5: 2026-Q1 | C5: 4 | D5: 4 | E5: 4 | F5: 4 | G5: 4 | H5: 4 | I5: 4 | J5: N | K5: =AVERAGE(tblPerformance[[#This Row],[KRA1]:[KRA5]]) -> 4 | L5: =ROUND((K5*0.6)+(H5*0.3)+(I5*0.1),2) -> 4
A6: EMP005 | B6: 2026-Q1 | C6: 2 | D6: 3 | E6: 2 | F6: 3 | G6: 2 | H6: 2 | I6: 3 | J6: N | K6: =AVERAGE(tblPerformance[[#This Row],[KRA1]:[KRA5]]) -> 2.4 | L6: =ROUND((K6*0.6)+(H6*0.3)+(I6*0.1),2) -> 2.34
A7: EMP006 | B7: 2026-Q1 | C7: 5 | D7: 4 | E7: 5 | F7: 5 | G7: 4 | H7: 5 | I7: 4 | J7: Y | K7: =AVERAGE(tblPerformance[[#This Row],[KRA1]:[KRA5]]) -> 4.6 | L7: =ROUND((K7*0.6)+(H7*0.3)+(I7*0.1),2) -> 4.66
A8: EMP007 | B8: 2026-Q1 | C8: 4 | D8: 4 | E8: 3 | F8: 4 | G8: 4 | H8: 4 | I8: 3 | J8: N | K8: =AVERAGE(tblPerformance[[#This Row],[KRA1]:[KRA5]]) -> 3.8 | L8: =ROUND((K8*0.6)+(H8*0.3)+(I8*0.1),2) -> 3.78
A9: EMP008 | B9: 2026-Q1 | C9: 3 | D9: 4 | E9: 3 | F9: 3 | G9: 4 | H9: 3 | I9: 4 | J9: N | K9: =AVERAGE(tblPerformance[[#This Row],[KRA1]:[KRA5]]) -> 3.4 | L9: =ROUND((K9*0.6)+(H9*0.3)+(I9*0.1),2) -> 3.34
A10: EMP009 | B10: 2026-Q1 | C10: 4 | D10: 5 | E10: 4 | F10: 4 | G10: 5 | H10: 4 | I10: 4 | J10: N | K10: =AVERAGE(tblPerformance[[#This Row],[KRA1]:[KRA5]]) -> 4.4 | L10: =ROUND((K10*0.6)+(H10*0.3)+(I10*0.1),2) -> 4.24
A11: EMP010 | B11: 2026-Q1 | C11: 5 | D11: 5 | E11: 4 | F11: 5 | G11: 5 | H11: 5 | I11: 5 | J11: Y | K11: =AVERAGE(tblPerformance[[#This Row],[KRA1]:[KRA5]]) -> 4.8 | L11: =ROUND((K11*0.6)+(H11*0.3)+(I11*0.1),2) -> 4.88
A12: EMP011 | B12: 2026-Q1 | C12: 3 | D12: 3 | E12: 3 | F12: 2 | G12: 3 | H12: 3 | I12: 3 | J12: N | K12: =AVERAGE(tblPerformance[[#This Row],[KRA1]:[KRA5]]) -> 2.8 | L12: =ROUND((K12*0.6)+(H12*0.3)+(I12*0.1),2) -> 2.88
A13: EMP012 | B13: 2026-Q1 | C13: 4 | D13: 4 | E13: 4 | F13: 4 | G13: 4 | H13: 4 | I13: 4 | J13: N | K13: =AVERAGE(tblPerformance[[#This Row],[KRA1]:[KRA5]]) -> 4 | L13: =ROUND((K13*0.6)+(H13*0.3)+(I13*0.1),2) -> 4
... A101: EMP100 | B101: 2026-Q1 | C101: 3 | D101: 3 | E101: 4 | F101: 3 | G101: 3 | H101: 3 | I101: 4 | J101: N | K101: =AVERAGE(tblPerformance[[#This Row],[KRA1]:[KRA5]]) -> 3.2 | L101: =ROUND((K101*0.6)+(H101*0.3)+(I101*0.1),2) -> 3.22

Sheet Holidays
A1: Date | B1: HolidayName | C1: Location_Org
A2: 46023 | B2: New Year | C2: India
A3: 46048 | B3: Republic Day | C3: India
A4: 46110 | B4: Holi | C4: India
A5: 46249 | B5: Independence Day | C5: India
A6: 46297 | B6: Gandhi Jayanti | C6: India
A7: 46315 | B7: Diwali | C7: India
A8: 46381 | B8: Christmas | C8: India

Sheet Shifts
A1: ShiftID | B1: ShiftName | C1: StartTime | D1: EndTime
A2: S1 | B2: Morning | C2: 0.375 | D2: 0.75
A3: S2 | B3: Afternoon | C3: 0.58333333 | D3: 0.95833333
A4: S3 | B4: Night | C4: 0.91666667 | D4: 0.29166667

Sheet Cleaned_Data
A1: Employee ID | B1: Employee Name | C1: Department | D1: Job Role | E1: Location | F1: Date | G1: Month | H1: Attendance Status | I1: Working Hours | J1: Overtime Hours | K1: Tasks Completed | L1: Performance Score | M1: Target Tasks | N1: Achievement % | O1: Salary | P1: Bonus Eligibility | Q1: Manager Rating | R1: Remarks
A2: EMP001 | B2: Rahul Nair | C2: Sales | D2: Sales Executive | E2: Mumbai | F2: 46007 | G2: 45992 | H2: Present | I2: 8.6 | J2: 0.7 | K2: 19 | L2: 10 | M2: 20 | N2: 0.95 | O2: 38253 | P2: Yes | Q2: 5
A3: EMP001 | B3: Rahul Nair | C3: Sales | D3: Sales Executive | E3: Mumbai | F3: 46050 | G3: 46023 | H3: Present | I3: 8.2 | J3: 2.4 | K3: 20 | L3: 8 | M3: 20 | N3: 1 | O3: 38253 | P3: Yes | Q3: 4 | R3: Strong team player
A4: EMP001 | B4: Rahul Nair | C4: Sales | D4: Sales Executive | E4: Mumbai | F4: 46059 | G4: 46054 | H4: Work From Home | I4: 8 | J4: 0.3 | K4: 18 | L4: 6 | M4: 20 | N4: 0.9 | O4: 38253 | P4: No | Q4: 2 | R4: Excellent work ethic
A5: EMP001 | B5: Rahul Nair | C5: Sales | D5: Sales Executive | E5: Mumbai | F5: 46101 | G5: 46082 | H5: Present | I5: 8 | J5: 0 | K5: 18 | L5: 7 | M5: 20 | N5: 0.9 | O5: 38253 | P5: No | Q5: 3 | R5: Excellent work ethic
A6: EMP002 | B6: Krishna Patel | C6: Sales | D6: Sales Manager | E6: Mumbai | F6: 46011 | G6: 45992 | H6: Absent | I6: 0 | J6: 0 | K6: 0 | L6: 4 | M6: 15 | N6: 0 | O6: 78543 | P6: No | Q6: 2 | R6: On track with targets
A7: EMP002 | B7: Krishna Patel | C7: Sales | D7: Sales Manager | E7: Mumbai | F7: 46031 | G7: 46023 | H7: Absent | I7: 0 | J7: 0 | K7: 0 | L7: 2 | M7: 15 | N7: 0 | O7: 78543 | P7: No | Q7: 1
A8: EMP002 | B8: Krishna Patel | C8: Sales | D8: Sales Manager | E8: Mumbai | F8: 46075 | G8: 46054 | H8: Work From Home | I8: 8 | J8: 0.9 | K8: 10 | L8: 7 | M8: 15 | N8: 0.6667 | O8: 78543 | P8: No | Q8: 3 | R8: Strong team player
A9: EMP002 | B9: Krishna Patel | C9: Sales | D9: Sales Manager | E9: Mumbai | F9: 46110 | G9: 46082 | H9: Present | I9: 8.1 | J9: 0.2 | K9: 18 | L9: 10 | M9: 15 | N9: 1.2 | O9: 78543 | P9: Yes | Q9: 4 | R9: Needs improvement
A10: EMP003 | B10: Sandeep Desai | C10: Sales | D10: Business Development Associate | E10: Mumbai | F10: 46016 | G10: 45992 | H10: Present | I10: 8.8 | J10: 0 | K10: 22 | L10: 6 | M10: 25 | N10: 0.88 | O10: 44837 | P10: No | Q10: 2
A11: EMP003 | B11: Sandeep Desai | C11: Sales | D11: Business Development Associate | E11: Mumbai | F11: 46032 | G11: 46023 | H11: Present | I11: 8.4 | J11: 1.5 | K11: 22 | L11: 8 | M11: 25 | N11: 0.88 | O11: 44837 | P11: No | Q11: 4 | R11: Frequent late coming
A12: EMP003 | B12: Sandeep Desai | C12: Sales | D12: Business Development Associate | E12: Mumbai | F12: 46054 | G12: 46054 | H12: Absent | I12: 0 | J12: 0 | K12: 0 | L12: 1 | M12: 25 | N12: 0 | O12: 44837 | P12: No | Q12: 1
A13: EMP003 | B13: Sandeep Desai | C13: Sales | D13: Business Development Associate | E13: Mumbai | F13: 46090 | G13: 46082 | H13: Absent | I13: 0 | J13: 0 | K13: 0 | L13: 1 | M13: 25 | N13: 0 | O13: 44837 | P13: No | Q13: 1
A14: EMP004 | B14: Vivaan Sharma | C14: Sales | D14: Sales Executive | E14: Mumbai | F14: 46008 | G14: 45992 | H14: Leave | I14: 0 | J14: 0 | K14: 0 | L14: 2 | M14: 20 | N14: 0 | O14: 37791 | P14: No | Q14: 1 | R14: Strong team player
A15: EMP004 | B15: Vivaan Sharma | C15: Sales | D15: Sales Executive | E15: Mumbai | F15: 46032 | G15: 46023 | H15: Work From Home | I15: 8.5 | J15: 0.4 | K15: 15 | L15: 8 | M15: 20 | N15: 0.75 | O15: 37791 | P15: No | Q15: 5 | R15: On track with targets
A16: EMP004 | B16: Vivaan Sharma | C16: Sales | D16: Sales Executive | E16: Mumbai | F16: 46073 | G16: 46054 | H16: Present | I16: 8.9 | J16: 0 | K16: 16 | L16: 8 | M16: 20 | N16: 0.8 | O16: 37791 | P16: No | Q16: 5 | R16: Consistent performer
A17: EMP004 | B17: Vivaan Sharma | C17: Sales | D17: Sales Executive | E17: Mumbai | F17: 46106 | G17: 46082 | H17: Present | I17: 8 | J17: 0.6 | K17: 13 | L17: 5 | M17: 20 | N17: 0.65 | O17: 37791 | P17: No | Q17: 3 | R17: On track with targets
A18: EMP005 | B18: Riya Agarwal | C18: Sales | D18: Sales Manager | E18: Mumbai | F18: 46021 | G18: 45992 | H18: Present | I18: 9.1 | J18: 0.7 | K18: 15 | L18: 9 | M18: 15 | N18: 1 | O18: 77597 | P18: Yes | Q18: 4 | R18: Consistent performer
A19: EMP005 | B19: Riya Agarwal | C19: Sales | D19: Sales Manager | E19: Mumbai | F19: 46038 | G19: 46023 | H19: Present | I19: 8.5 | J19: 2.3 | K19: 13 | L19: 10 | M19: 15 | N19: 0.8667 | O19: 77597 | P19: No | Q19: 3 | R19: Consistent performer
A20: EMP005 | B20: Riya Agarwal | C20: Sales | D20: Sales Manager | E20: Mumbai | F20: 46080 | G20: 46054 | H20: Work From Home | I20: 8.8 | J20: 0.9 | K20: 12 | L20: 8 | M20: 15 | N20: 0.8 | O20: 77597 | P20: No | Q20: 3 | R20: Good performance
A21: EMP005 | B21: Riya Agarwal | C21: Sales | D21: Sales Manager | E21: Mumbai | F21: 46083 | G21: 46082 | H21: Present | I21: 8.2 | J21: 1.2 | K21: 17 | L21: 9 | M21: 15 | N21: 1.1333 | O21: 77597 | P21: Yes | Q21: 4 | R21: Requires coaching
A22: EMP006 | B22: Reyansh Desai | C22: IT | D22: Software Engineer | E22: Pune | F22: 46022 | G22: 45992 | H22: Present | I22: 8 | J22: 1.7 | K22: 23 | L22: 8 | M22: 25 | N22: 0.92 | O22: 64805 | P22: Yes | Q22: 4
A23: EMP006 | B23: Reyansh Desai | C23: IT | D23: Software Engineer | E23: Pune | F23: 46038 | G23: 46023 | H23: Work From Home | I23: 8.4 | J23: 1.8 | K23: 18 | L23: 7 | M23: 25 | N23: 0.72 | O23: 64805 | P23: No | Q23: 3 | R23: On track with targets
A24: EMP006 | B24: Reyansh Desai | C24: IT | D24: Software Engineer | E24: Pune | F24: 46078 | G24: 46054 | H24: Present | I24: 7.4 | J24: 1.1 | K24: 22 | L24: 8 | M24: 25 | N24: 0.88 | O24: 64805 | P24: No | Q24: 4 | R24: Strong team player
A25: EMP006 | B25: Reyansh Desai | C25: IT | D25: Software Engineer | E25: Pune | F25: 46097 | G25: 46082 | H25: Leave | I25: 0 | J25: 0 | K25: 0 | L25: 1 | M25: 25 | N25: 0 | O25: 64805 | P25: No | Q25: 1
A26: EMP007 | B26: Anika Mehta | C26: IT | D26: System Analyst | E26: Mumbai | F26: 46000 | G26: 45992 | H26: Present | I26: 8.1 | J26: 0 | K26: 21 | L26: 8 | M26: 25 | N26: 0.84 | O26: 57307 | P26: No | Q26: 5 | R26: Requires coaching
A27: EMP007 | B27: Anika Mehta | C27: IT | D27: System Analyst | E27: Mumbai | F27: 46036 | G27: 46023 | H27: Absent | I27: 0 | J27: 0 | K27: 0 | L27: 2 | M27: 25 | N27: 0 | O27: 57307 | P27: No | Q27: 1 | R27: On track with targets
A28: EMP007 | B28: Anika Mehta | C28: IT | D28: System Analyst | E28: Mumbai | F28: 46078 | G28: 46054 | H28: Work From Home | I28: 8.3 | J28: 0 | K28: 21 | L28: 8 | M28: 25 | N28: 0.84 | O28: 57307 | P28: No | Q28: 5 | R28: Good performance
A29: EMP007 | B29: Anika Mehta | C29: IT | D29: System Analyst | E29: Mumbai | F29: 46104 | G29: 46082 | H29: Present | I29: 8.2 | J29: 1.1 | K29: 21 | L29: 6 | M29: 25 | N29: 0.84 | O29: 57307 | P29: No | Q29: 4 | R29: Strong team player
A30: EMP008 | B30: Ananya Mehta | C30: IT | D30: IT Support Engineer | E30: Bangalore | F30: 46012 | G30: 45992 | H30: Present | I30: 8.8 | J30: 1.6 | K30: 15 | L30: 9 | M30: 22 | N30: 0.6818 | O30: 39763 | P30: No | Q30: 4 | R30: On track with targets
A31: EMP008 | B31: Ananya Mehta | C31: IT | D31: IT Support Engineer | E31: Bangalore | F31: 46037 | G31: 46023 | H31: Present | I31: 8.7 | J31: 3 | K31: 15 | L31: 6 | M31: 22 | N31: 0.6818 | O31: 39763 | P31: No | Q31: 3 | R31: Good performance
A32: EMP008 | B32: Ananya Mehta | C32: IT | D32: IT Support Engineer | E32: Bangalore | F32: 46056 | G32: 46054 | H32: Present | I32: 8 | J32: 0 | K32: 19 | L32: 7 | M32: 22 | N32: 0.8636 | O32: 39763 | P32: No | Q32: 4 | R32: Requires coaching
A33: EMP008 | B33: Ananya Mehta | C33: IT | D33: IT Support Engineer | E33: Bangalore | F33: 46099 | G33: 46082 | H33: Present | I33: 7.7 | J33: 2.3 | K33: 16 | L33: 7 | M33: 22 | N33: 0.7273 | O33: 39763 | P33: No | Q33: 4 | R33: Good performance
A34: EMP009 | B34: Vihaan Iyer | C34: IT | D34: Software Engineer | E34: Pune | F34: 45992 | G34: 45992 | H34: Present | I34: 7.6 | J34: 1 | K34: 24 | L34: 8 | M34: 22 | N34: 1.0909 | O34: 63792 | P34: Yes | Q34: 4 | R34: Strong team player
A35: EMP009 | B35: Vihaan Iyer | C35: IT | D35: Software Engineer | E35: Pune | F35: 46024 | G35: 46023 | H35: Present | I35: 8.5 | J35: 1.6 | K35: 14 | L35: 5 | M35: 22 | N35: 0.6364 | O35: 63792 | P35: No | Q35: 3
A36: EMP009 | B36: Vihaan Iyer | C36: IT | D36: Software Engineer | E36: Pune | F36: 46081 | G36: 46054 | H36: Present | I36: 8.5 | J36: 1.1 | K36: 20 | L36: 7 | M36: 22 | N36: 0.9091 | O36: 63792 | P36: No | Q36: 4 | R36: On track with targets
A37: EMP009 | B37: Vihaan Iyer | C37: IT | D37: Software Engineer | E37: Pune | F37: 46089 | G37: 46082 | H37: Present | I37: 8.5 | J37: 0.1 | K37: 26 | L37: 10 | M37: 22 | N37: 1.1818 | O37: 63792 | P37: Yes | Q37: 4 | R37: Frequent late coming
A38: EMP010 | B38: Sneha Rao | C38: IT | D38: System Analyst | E38: Chennai | F38: 45998 | G38: 45992 | H38: Present | I38: 8.7 | J38: 0 | K38: 18 | L38: 10 | M38: 18 | N38: 1 | O38: 58166 | P38: Yes | Q38: 5
A39: EMP010 | B39: Sneha Rao | C39: IT | D39: System Analyst | E39: Chennai | F39: 46052 | G39: 46023 | H39: Leave | I39: 0 | J39: 0 | K39: 0 | L39: 3 | M39: 18 | N39: 0 | O39: 58166 | P39: No | Q39: 2 | R39: Requires coaching
A40: EMP010 | B40: Sneha Rao | C40: IT | D40: System Analyst | E40: Chennai | F40: 46069 | G40: 46054 | H40: Present | I40: 8.8 | J40: 2.7 | K40: 15 | L40: 7 | M40: 18 | N40: 0.8333 | O40: 58166 | P40: No | Q40: 3 | R40: Frequent late coming
...

Sheet EmployeeMetrics
B4: EmployeeID | C4: Name | D4: Department | E4: JobRole | F4: Manager | G4: Attendance% | H4: PresentDays | I4: AbsentDays | J4: LateMins | K4: OTHours | L4: PerfScore | M4: AttendanceFlag | N4: PerfFlag | O4: RiskTag
B5: =Employees!A2 -> EMP001 | C5: =Employees!B2 -> Liam Smith | D5: =Employees!F2 -> IT | E5: =Employees!G2 -> Software Engineer | F5: =Employees!H2 -> Manish Sharma | G5: =Attendance!G2 -> 1 | H5: =IF(OR(Attendance!C2="P",Attendance!C2="WFH"),1,0) -> 1 | I5: =IF(Attendance!C2="A",1,0) -> 0 | J5: =0 -> 0 | K5: =Attendance!F2 -> 0 | L5: =VLOOKUP(B5,Performance!$A:$L,12,FALSE) -> 4 | M5: =IF(G5<90%,"LOW","OK") -> OK | N5: =IF(L5<3,"LOW","OK") -> OK | O5: =IF(AND(G5<90%,L5<3),"High Risk",IF(G5<90%,"Attendance Risk",IF(L5<3,"Performance Risk","OK"))) -> OK
B6: =Employees!A3 -> EMP002 | C6: =Employees!B3 -> Emma Smith | D6: =Employees!F3 -> HR | E6: =Employees!G3 -> HR Executive | F6: =Employees!H3 -> Anita Desai | G6: =Attendance!G3 -> 1 | H6: =IF(OR(Attendance!C3="P",Attendance!C3="WFH"),1,0) -> 1 | I6: =IF(Attendance!C3="A",1,0) -> 0 | J6: =0 -> 0 | K6: =Attendance!F3 -> 0.5 | L6: =VLOOKUP(B6,Performance!$A:$L,12,FALSE) -> 4.88 | M6: =IF(G6<90%,"LOW","OK") -> OK | N6: =IF(L6<3,"LOW","OK") -> OK | O6: =IF(AND(G6<90%,L6<3),"High Risk",IF(G6<90%,"Attendance Risk",IF(L6<3,"Performance Risk","OK"))) -> OK
B7: =Employees!A4 -> EMP003 | C7: =Employees!B4 -> Noah Smith | D7: =Employees!F4 -> Finance | E7: =Employees!G4 -> Accountant | F7: =Employees!H4 -> Suresh Kumar | G7: =Attendance!G4 -> 0 | H7: =IF(OR(Attendance!C4="P",Attendance!C4="WFH"),1,0) -> 0 | I7: =IF(Attendance!C4="A",1,0) -> 1 | J7: =0 -> 0 | K7: =Attendance!F4 -> 0 | L7: =VLOOKUP(B7,Performance!$A:$L,12,FALSE) -> 3.12 | M7: =IF(G7<90%,"LOW","OK") -> LOW | N7: =IF(L7<3,"LOW","OK") -> OK | O7: =IF(AND(G7<90%,L7<3),"High Risk",IF(G7<90%,"Attendance Risk",IF(L7<3,"Performance Risk","OK"))) -> Attendance Risk
B8: =Employees!A5 -> EMP004 | C8: =Employees!B5 -> Olivia Smith | D8: =Employees!F5 -> Operations | E8: =Employees!G5 -> Operations Associate | F8: =Employees!H5 -> Meera Nair | G8: =Attendance!G5 -> 1 | H8: =IF(OR(Attendance!C5="P",Attendance!C5="WFH"),1,0) -> 1 | I8: =IF(Attendance!C5="A",1,0) -> 0 | J8: =0 -> 0 | K8: =Attendance!F5 -> 0 | L8: =VLOOKUP(B8,Performance!$A:$L,12,FALSE) -> 4 | M8: =IF(G8<90%,"LOW","OK") -> OK | N8: =IF(L8<3,"LOW","OK") -> OK | O8: =IF(AND(G8<90%,L8<3),"High Risk",IF(G8<90%,"Attendance Risk",IF(L8<3,"Performance Risk","OK"))) -> OK
B9: =Employees!A6 -> EMP005 | C9: =Employees!B6 -> Oliver Smith | D9: =Employees!F6 -> IT | E9: =Employees!G6 -> Team Lead | F9: =Employees!H6 -> Manish Sharma | G9: =Attendance!G6 -> 1 | H9: =IF(OR(Attendance!C6="P",Attendance!C6="WFH"),1,0) -> 1 | I9: =IF(Attendance!C6="A",1,0) -> 0 | J9: =0 -> 0 | K9: =Attendance!F6 -> 0 | L9: =VLOOKUP(B9,Performance!$A:$L,12,FALSE) -> 2.34 | M9: =IF(G9<90%,"LOW","OK") -> OK | N9: =IF(L9<3,"LOW","OK") -> LOW | O9: =IF(AND(G9<90%,L9<3),"High Risk",IF(G9<90%,"Attendance Risk",IF(L9<3,"Performance Risk","OK"))) -> Performance Risk
B10: =Employees!A7 -> EMP006 | C10: =Employees!B7 -> Ava Smith | D10: =Employees!F7 -> HR | E10: =Employees!G7 -> HR Manager | F10: =Employees!H7 -> Anita Desai | G10: =Attendance!G7 -> 1 | H10: =IF(OR(Attendance!C7="P",Attendance!C7="WFH"),1,0) -> 1 | I10: =IF(Attendance!C7="A",1,0) -> 0 | J10: =0 -> 0 | K10: =Attendance!F7 -> 0 | L10: =VLOOKUP(B10,Performance!$A:$L,12,FALSE) -> 4.66 | M10: =IF(G10<90%,"LOW","OK") -> OK | N10: =IF(L10<3,"LOW","OK") -> OK | O10: =IF(AND(G10<90%,L10<3),"High Risk",IF(G10<90%,"Attendance Risk",IF(L10<3,"Performance Risk","OK"))) -> OK
B11: =Employees!A8 -> EMP007 | C11: =Employees!B8 -> Elijah Smith | D11: =Employees!F8 -> Finance | E11: =Employees!G8 -> Financial Analyst | F11: =Employees!H8 -> Suresh Kumar | G11: =Attendance!G8 -> 1 | H11: =IF(OR(Attendance!C8="P",Attendance!C8="WFH"),1,0) -> 1 | I11: =IF(Attendance!C8="A",1,0) -> 0 | J11: =0 -> 0 | K11: =Attendance!F8 -> 1 | L11: =VLOOKUP(B11,Performance!$A:$L,12,FALSE) -> 3.78 | M11: =IF(G11<90%,"LOW","OK") -> OK | N11: =IF(L11<3,"LOW","OK") -> OK | O11: =IF(AND(G11<90%,L11<3),"High Risk",IF(G11<90%,"Attendance Risk",IF(L11<3,"Performance Risk","OK"))) -> OK
B12: =Employees!A9 -> EMP008 | C12: =Employees!B9 -> Sophia Smith | D12: =Employees!F9 -> Operations | E12: =Employees!G9 -> Operations Manager | F12: =Employees!H9 -> Meera Nair | G12: =Attendance!G9 -> 1 | H12: =IF(OR(Attendance!C9="P",Attendance!C9="WFH"),1,0) -> 1 | I12: =IF(Attendance!C9="A",1,0) -> 0 | J12: =0 -> 0 | K12: =Attendance!F9 -> 0 | L12: =VLOOKUP(B12,Performance!$A:$L,12,FALSE) -> 3.34 | M12: =IF(G12<90%,"LOW","OK") -> OK | N12: =IF(L12<3,"LOW","OK") -> OK | O12: =IF(AND(G12<90%,L12<3),"High Risk",IF(G12<90%,"Attendance Risk",IF(L12<3,"Performance Risk","OK"))) -> OK
B13: =Employees!A10 -> EMP009 | C13: =Employees!B10 -> William Smith | D13: =Employees!F10 -> IT | E13: =Employees!G10 -> Software Engineer | F13: =Employees!H10 -> Manish Sharma | G13: =Attendance!G10 -> 0 | H13: =IF(OR(Attendance!C10="P",Attendance!C10="WFH"),1,0) -> 0 | I13: =IF(Attendance!C10="A",1,0) -> 0 | J13: =0 -> 0 | K13: =Attendance!F10 -> 0 | L13: =VLOOKUP(B13,Performance!$A:$L,12,FALSE) -> 4.24 | M13: =IF(G13<90%,"LOW","OK") -> LOW | N13: =IF(L13<3,"LOW","OK") -> OK | O13: =IF(AND(G13<90%,L13<3),"High Risk",IF(G13<90%,"Attendance Risk",IF(L13<3,"Performance Risk","OK"))) -> Attendance Risk
B14: =Employees!A11 -> EMP010 | C14: =Employees!B11 -> Isabella Smith | D14: =Employees!F11 -> Finance | E14: =Employees!G11 -> Accountant | F14: =Employees!H11 -> Suresh Kumar | G14: =Attendance!G11 -> 1 | H14: =IF(OR(Attendance!C11="P",Attendance!C11="WFH"),1,0) -> 1 | I14: =IF(Attendance!C11="A",1,0) -> 0 | J14: =0 -> 0 | K14: =Attendance!F11 -> 0 | L14: =VLOOKUP(B14,Performance!$A:$L,12,FALSE) -> 4.88 | M14: =IF(G14<90%,"LOW","OK") -> OK | N14: =IF(L14<3,"LOW","OK") -> OK | O14: =IF(AND(G14<90%,L14<3),"High Risk",IF(G14<90%,"Attendance Risk",IF(L14<3,"Performance Risk","OK"))) -> OK
B15: =Employees!A12 -> EMP011 | C15: =Employees!B12 -> Liam Johnson | D15: =Employees!F12 -> IT | E15: =Employees!G12 -> Software Engineer | F15: =Employees!H12 -> Manish Sharma | G15: =Attendance!G12 -> 1 | H15: =IF(OR(Attendance!C12="P",Attendance!C12="WFH"),1,0) -> 1 | I15: =IF(Attendance!C12="A",1,0) -> 0 | J15: =0 -> 0 | K15: =Attendance!F12 -> 0 | L15: =VLOOKUP(B15,Performance!$A:$L,12,FALSE) -> 2.88 | M15: =IF(G15<90%,"LOW","OK") -> OK | N15: =IF(L15<3,"LOW","OK") -> LOW | O15: =IF(AND(G15<90%,L15<3),"High Risk",IF(G15<90%,"Attendance Risk",IF(L15<3,"Performance Risk","OK"))) -> Performance Risk
B16: =Employees!A13 -> EMP012 | C16: =Employees!B13 -> Emma Johnson | D16: =Employees!F13 -> HR | E16: =Employees!G13 -> HR Executive | F16: =Employees!H13 -> Anita Desai | G16: =Attendance!G13 -> 1 | H16: =IF(OR(Attendance!C13="P",Attendance!C13="WFH"),1,0) -> 1 | I16: =IF(Attendance!C13="A",1,0) -> 0 | J16: =0 -> 0 | K16: =Attendance!F13 -> 0 | L16: =VLOOKUP(B16,Performance!$A:$L,12,FALSE) -> 4 | M16: =IF(G16<90%,"LOW","OK") -> OK | N16: =IF(L16<3,"LOW","OK") -> OK | O16: =IF(AND(G16<90%,L16<3),"High Risk",IF(G16<90%,"Attendance Risk",IF(L16<3,"Performance Risk","OK"))) -> OK
... B104: =Employees!A101 -> EMP100 | C104: =Employees!B101 -> Isabella Martinez | D104: =Employees!F101 -> Finance | E104: =Employees!G101 -> Accountant | F104: =Employees!H101 -> Suresh Kumar | G104: =Attendance!G101 -> 1 | H104: =IF(OR(Attendance!C101="P",Attendance!C101="WFH"),1,0) -> 1 | I104: =IF(Attendance!C101="A",1,0) -> 0 | J104: =0 -> 0 | K104: =Attendance!F101 -> 0 | L104: =VLOOKUP(B104,Performance!$A:$L,12,FALSE) -> 3.22 | M104: =IF(G104<90%,"LOW","OK") -> OK | N104: =IF(L104<3,"LOW","OK") -> OK | O104: =IF(AND(G104<90%,L104<3),"High Risk",IF(G104<90%,"Attendance Risk",IF(L104<3,"Performance Risk","OK"))) -> OK

Sheet Pivot table
A1: Row Labels | B1: Total Employees
A2: Finance | B2: 20
A3: HR | B3: 20
A4: IT | B4: 20
A5: Operations | B5: 20
A6: Sales | B6: 20
A7: Grand Total | B7: 100
A12: Row Labels | B12: Average of Performance Score
A13: Finance | B13: 7.9
A14: HR | B14: 6.9
A15: IT | B15: 6.8
A16: Operations | B16: 5.85
A17: Sales | B17: 6.45
A18: Grand Total | B18: 6.78
A23: Row Labels | B23: Count of Attendance Status
A24: Absent | B24: 8
A25: Leave | B25: 10
A26: Present | B26: 72
A27: Work From Home | B27: 10
A28: Grand Total | B28: 100
A32: Row Labels | B32: Average of Performance Score
A33: 45992 | B33: 7.08
A34: 46023 | B34: 6.8
A35: 46054 | B35: 6.64
A36: 46082 | B36: 6.6
A37: Grand Total | B37: 6.78
A40: Row Labels | B40: Sum of Tasks Completed | C40: Sum of Target Tasks
A41: Finance | B41: 344 | C41: 404
A42: HR | B42: 248 | C42: 372
A43: IT | B43: 324 | C43: 448
A44: Operations | B44: 231 | C44: 388
A45: Sales | B45: 248 | C45: 380
A46: Grand Total | B46: 1395 | C46: 1992
A51: Row Labels | B51: Average of Overtime Hours
A52: Finance | B52: 0.545
A53: HR | B53: 0.92
A54: IT | B54: 0.99
A55: Operations | B55: 0.71
A56: Sales | B56: 0.605
A57: Grand Total | B57: 0.754
...

Sheet Dashboard
F3: HR ANALYTICS DASHBOARD
B6: HEADCOUNT | E6: AVG ATTENDANCE % (SELECTED MONTH) | H6: AVG PERFORMANCE SCORE | K6: HIGH RISK EMPLOYEES
B7: =GETPIVOTDATA("Employee ID",'Pivot table'!$A$1) -> 100 | E7: =GETPIVOTDATA("Attendance%",'Pivot table'!$A$116) -> 0.95 | H7: =GETPIVOTDATA("Performance Score",'Pivot table'!$A$12) -> 6.78 | K7: =GETPIVOTDATA("EmployeeID",'Pivot table'!$A$107,"RiskTag","High Risk") -> 3
B10: HIGH PERFORMERS (Score >= 4) | E10: LOW PERFORMERS (Score < 3) | H10: AVG OVERTIME HRS / EMPLOYEE | K10: TOTAL ABSENCES (SELECTED MONTH)
B11: =GETPIVOTDATA("EmployeeID",'Pivot table'!$A$100,"PerfFlag","OK") -> 85 | E11: =GETPIVOTDATA("EmployeeID",'Pivot table'!$A$100,"PerfFlag","LOW") -> 15 | H11: =GETPIVOTDATA("Overtime Hours",'Pivot table'!$A$51) -> 0.754 | K11: =GETPIVOTDATA("Attendance Status",'Pivot table'!$A$23,"Attendance Status","Absent") -> 8

Sheet Lists
A1: Status | B1: EmpType | C1: Awards | D1: Departments
A2: P | B2: Full-Time | C2: Y | D2: HR
A3: A | B3: Part-Time | C3: N | D3: Finance
A4: L | B4: Contract | D4: IT
A5: WFH | B5: Intern | D5: Operations
A6: WO
A7: H
